2020-01-15 16:22:39,976 (40278/MainThread) pgcli.main INFO - No default pager found in environment. Using os default pager
2020-01-15 16:22:43,853 (40278/MainThread) pgcli.main ERROR - traceback: 'Traceback (most recent call last):\n  File "/anaconda3/lib/python3.7/site-packages/pgcli/main.py", line 566, in connect\n    raise e\n  File "/anaconda3/lib/python3.7/site-packages/pgcli/main.py", line 553, in connect\n    pgexecute = PGExecute(database, user, passwd, host, port, dsn, **kwargs)\n  File "/anaconda3/lib/python3.7/site-packages/pgcli/pgexecute.py", line 215, in __init__\n    self.connect(database, user, password, host, port, dsn, **kwargs)\n  File "/anaconda3/lib/python3.7/site-packages/pgcli/pgexecute.py", line 255, in connect\n    conn = psycopg2.connect(**conn_params)\n  File "/anaconda3/lib/python3.7/site-packages/psycopg2/__init__.py", line 126, in connect\n    conn = _connect(dsn, connection_factory=connection_factory, **kwasync)\n  File "/anaconda3/lib/python3.7/site-packages/pgcli/pgexecute.py", line 40, in _wait_select\n    state = conn.poll()\npsycopg2.OperationalError: FATAL:  database "studies-dev" does not exist\n\n'
2020-01-15 16:22:51,500 (40287/MainThread) pgcli.main INFO - No default pager found in environment. Using os default pager
2020-01-15 16:23:50,416 (40287/MainThread) pgcli.pgexecute ERROR - sql: 'ls', error: SyntaxError('syntax error at or near "ls"\nLINE 1: ls\n        ^\n')
2020-01-15 16:23:50,417 (40287/MainThread) pgcli.pgexecute ERROR - traceback: 'Traceback (most recent call last):\n  File "/anaconda3/lib/python3.7/site-packages/pgcli/pgexecute.py", line 413, in run\n    yield self.execute_normal_sql(sql) + (sql, True, False)\n  File "/anaconda3/lib/python3.7/site-packages/pgcli/pgexecute.py", line 448, in execute_normal_sql\n    cur.execute(split_sql)\npsycopg2.errors.SyntaxError: syntax error at or near "ls"\nLINE 1: ls\n        ^\n\n'
2020-01-15 16:24:17,613 (40287/MainThread) pgcli.pgexecute ERROR - sql: 'ls', error: SyntaxError('syntax error at or near "ls"\nLINE 1: ls\n        ^\n')
2020-01-15 16:24:17,613 (40287/MainThread) pgcli.pgexecute ERROR - traceback: 'Traceback (most recent call last):\n  File "/anaconda3/lib/python3.7/site-packages/pgcli/pgexecute.py", line 413, in run\n    yield self.execute_normal_sql(sql) + (sql, True, False)\n  File "/anaconda3/lib/python3.7/site-packages/pgcli/pgexecute.py", line 448, in execute_normal_sql\n    cur.execute(split_sql)\npsycopg2.errors.SyntaxError: syntax error at or near "ls"\nLINE 1: ls\n        ^\n\n'
2020-01-15 16:29:34,202 (40287/MainThread) pgcli.pgexecute ERROR - sql: 'SELECT * FROM studies', error: QueryCanceled('canceling statement due to user request\n')
2020-01-15 16:29:34,203 (40287/MainThread) pgcli.pgexecute ERROR - traceback: 'Traceback (most recent call last):\n  File "/anaconda3/lib/python3.7/site-packages/pgcli/pgexecute.py", line 413, in run\n    yield self.execute_normal_sql(sql) + (sql, True, False)\n  File "/anaconda3/lib/python3.7/site-packages/pgcli/pgexecute.py", line 448, in execute_normal_sql\n    cur.execute(split_sql)\npsycopg2.errors.QueryCanceled: canceling statement due to user request\n\n'
